---
title: "#django manage.py createsuperuser でエラーが出る場合の対処 ( django.db.utils.Opera"
emoji: "🖥"
type: "tech"
topics: ["Django"]
published: true
published_at: 2019-04-29t12:01
---

# resolve

事前に migrate しておこう

```
$ python manage.py migrate
Operations to perform:
  Apply all migrations: admin, auth, contenttypes, sessions
Running migrations:
  Applying contenttypes.0001_initial... OK
  Applying auth.0001_initial... OK
  Applying admin.0001_initial... OK
  Applying admin.0002_logentry_remove_auto_add... OK
  Applying admin.0003_logentry_add_action_flag_choices... OK
  Applying contenttypes.0002_remove_content_type_name... OK
  Applying auth.0002_alter_permission_name_max_length... OK
  Applying auth.0003_alter_user_email_max_length... OK
  Applying auth.0004_alter_user_username_opts... OK
  Applying auth.0005_alter_user_last_login_null... OK
  Applying auth.0006_require_contenttypes_0002... OK
  Applying auth.0007_alter_validators_add_error_messages... OK
  Applying auth.0008_alter_user_username_max_length... OK
  Applying auth.0009_alter_user_last_name_max_length... OK
  Applying auth.0010_alter_group_name_max_length... OK
  Applying auth.0011_update_proxy_permissions... OK
  Applying sessions.0001_initial... OK

```

# Error

なぜに例外だよ

```
$ python manage.py createsuperuser

You have 17 unapplied migration(s). Your project may not work properly until you apply the migrations for app(s): admin, auth, contenttypes, sessions.
Run 'python manage.py migrate' to apply them.

Traceback (most recent call last):
  File "/Users/yumainaura/.pyenv/versions/3.7.3/lib/python3.7/site-packages/django/db/backends/utils.py", line 84, in _execute
    return self.cursor.execute(sql, params)
  File "/Users/yumainaura/.pyenv/versions/3.7.3/lib/python3.7/site-packages/django/db/backends/sqlite3/base.py", line 383, in execute
    return Database.Cursor.execute(self, query, params)
sqlite3.OperationalError: no such table: auth_user

The above exception was the direct cause of the following exception:

Traceback (most recent call last):
  File "manage.py", line 21, in <module>
    main()
  File "manage.py", line 17, in main
    execute_from_command_line(sys.argv)
  File "/Users/yumainaura/.pyenv/versions/3.7.3/lib/python3.7/site-packages/django/core/management/__init__.py", line 381, in execute_from_command_line
    utility.execute()
  File "/Users/yumainaura/.pyenv/versions/3.7.3/lib/python3.7/site-packages/django/core/management/__init__.py", line 375, in execute
    self.fetch_command(subcommand).run_from_argv(self.argv)
  File "/Users/yumainaura/.pyenv/versions/3.7.3/lib/python3.7/site-packages/django/core/management/base.py", line 323, in run_from_argv
    self.execute(*args, **cmd_options)
  File "/Users/yumainaura/.pyenv/versions/3.7.3/lib/python3.7/site-packages/django/contrib/auth/management/commands/createsuperuser.py", line 61, in execute
    return super().execute(*args, **options)
  File "/Users/yumainaura/.pyenv/versions/3.7.3/lib/python3.7/site-packages/django/core/management/base.py", line 364, in execute
    output = self.handle(*args, **options)
  File "/Users/yumainaura/.pyenv/versions/3.7.3/lib/python3.7/site-packages/django/contrib/auth/management/commands/createsuperuser.py", line 82, in handle
    default_username = get_default_username()
  File "/Users/yumainaura/.pyenv/versions/3.7.3/lib/python3.7/site-packages/django/contrib/auth/management/__init__.py", line 140, in get_default_username
    auth_app.User._default_manager.get(username=default_username)
  File "/Users/yumainaura/.pyenv/versions/3.7.3/lib/python3.7/site-packages/django/db/models/manager.py", line 82, in manager_method
    return getattr(self.get_queryset(), name)(*args, **kwargs)
  File "/Users/yumainaura/.pyenv/versions/3.7.3/lib/python3.7/site-packages/django/db/models/query.py", line 402, in get
    num = len(clone)
  File "/Users/yumainaura/.pyenv/versions/3.7.3/lib/python3.7/site-packages/django/db/models/query.py", line 256, in __len__
    self._fetch_all()
  File "/Users/yumainaura/.pyenv/versions/3.7.3/lib/python3.7/site-packages/django/db/models/query.py", line 1242, in _fetch_all
    self._result_cache = list(self._iterable_class(self))
  File "/Users/yumainaura/.pyenv/versions/3.7.3/lib/python3.7/site-packages/django/db/models/query.py", line 55, in __iter__
    results = compiler.execute_sql(chunked_fetch=self.chunked_fetch, chunk_size=self.chunk_size)
  File "/Users/yumainaura/.pyenv/versions/3.7.3/lib/python3.7/site-packages/django/db/models/sql/compiler.py", line 1097, in execute_sql
    cursor.execute(sql, params)
  File "/Users/yumainaura/.pyenv/versions/3.7.3/lib/python3.7/site-packages/django/db/backends/utils.py", line 99, in execute
    return super().execute(sql, params)
  File "/Users/yumainaura/.pyenv/versions/3.7.3/lib/python3.7/site-packages/django/db/backends/utils.py", line 67, in execute
    return self._execute_with_wrappers(sql, params, many=False, executor=self._execute)
  File "/Users/yumainaura/.pyenv/versions/3.7.3/lib/python3.7/site-packages/django/db/backends/utils.py", line 76, in _execute_with_wrappers
    return executor(sql, params, many, context)
  File "/Users/yumainaura/.pyenv/versions/3.7.3/lib/python3.7/site-packages/django/db/backends/utils.py", line 84, in _execute
    return self.cursor.execute(sql, params)
  File "/Users/yumainaura/.pyenv/versions/3.7.3/lib/python3.7/site-packages/django/db/utils.py", line 89, in __exit__
    raise dj_exc_value.with_traceback(traceback) from exc_value
  File "/Users/yumainaura/.pyenv/versions/3.7.3/lib/python3.7/site-packages/django/db/backends/utils.py", line 84, in _execute
    return self.cursor.execute(sql, params)
  File "/Users/yumainaura/.pyenv/versions/3.7.3/lib/python3.7/site-packages/django/db/backends/sqlite3/base.py", line 383, in execute
    return Database.Cursor.execute(self, query, params)
django.db.utils.OperationalError: no such table: auth_user
```

# Original by Github issue

https://github.com/YumaInaura/YumaInaura/issues/1506








<!-- Update From Qiita API -->

# チャットメンバー募集


何か質問、悩み事、相談などあればLINEオープンチャットもご利用ください。

https://line.me/ti/g2/eEPltQ6Tzh3pYAZV8JXKZqc7PJ6L0rpm573dcQ





# Twitter


https://twitter.com/YumaInaura


<!-- Update From Qiita API -->



# 公開日時

2019-04-29
